Workbook
Name Datenschnitt_Jahr: KPI!$M$2:$M$7
Name Datenschnitt_Projekt: KPI!$N$2:$N$17

Sheet KPI
A1: Dashboard 80681 – Steuerung und Berechnungen | M1: Jahres-Auswahlliste | N1: Projekt-Auswahlliste
A2: Auswahljahr | B2: =Dashboard!$B$4 -> 2026 | M2: 2021 | N2: Gesamtportfolio
A3: Projekt | B3: =Dashboard!$E$4 -> Gesamtportfolio | M3: 2022 | N3: Medizinische Betreuung Obdachloser
A4: Vorjahr | B4: =B2-1 -> 2025 | M4: 2023 | N4: Café Krause
A5: Datenstatus | B5: =IF(B2=MAX(Dashboard_Daten!$A$2:$A$70),"Hochrechnung","Jahresabschluss") -> Hochrechnung | M5: 2024 | N5: WoTa "Am Wassertor"
A6: Datenzeilen aktuell | B6: =IF(B3="Gesamtportfolio",COUNTIF(Dashboard_Daten!$A$2:$A$70,B2),COUNTIFS(Dashboard_Daten!$A$2:$A$70,B2,Dashboard_Daten!$C$2:$C$70,B3)) -> 5 | M6: 2025 | N6: EHAP-Projekt
A7: Datenzeilen Vorjahr | B7: =IF(B3="Gesamtportfolio",COUNTIF(Dashboard_Daten!$A$2:$A$70,B4),COUNTIFS(Dashboard_Daten!$A$2:$A$70,B4,Dashboard_Daten!$C$2:$C$70,B3)) -> 7 | M7: 2026 | N7: WoTa Kiez Cafe
N8: WoTa Bürgerhilfe
A9: Kennzahl | B9: Aktuell | C9: Vorjahr | D9: Δ absolut | E9: Δ % / pp | N9: Sprachmittler für Bewohner der Str.d.Pariser Kommune
A10: Refinanzierungssaldo | B10: =IF($B$6=0,"",IF($B$3="Gesamtportfolio",SUMIFS(Dashboard_Daten!$V$2:$V$70,Dashboard_Daten!$A$2:$A$70,$B$2),SUMIFS(Dashboard_Daten!$V$2:$V$70,Dashboard_Daten!$A$2:$A$70,$B$2,Dashboard_Daten!$C$2:$C$70,$B$3))) -> 283119.91 | C10: =IF($B$7=0,"",IF($B$3="Gesamtportfolio",SUMIFS(Dashboard_Daten!$V$2:$V$70,Dashboard_Daten!$A$2:$A$70,$B$4),SUMIFS(Dashboard_Daten!$V$2:$V$70,Dashboard_Daten!$A$2:$A$70,$B$4,Dashboard_Daten!$C$2:$C$70,$B$3))) -> 173212.81 | D10: =IF(OR(B10="",C10=""),"",B10-C10) -> 109907.1 | N10: Weihnachtsfeier für Wohnungslose Männer
A11: Refinanzierungsertrag | B11: =IF($B$6=0,"",IF($B$3="Gesamtportfolio",SUMIFS(Dashboard_Daten!$X$2:$X$70,Dashboard_Daten!$A$2:$A$70,$B$2),SUMIFS(Dashboard_Daten!$X$2:$X$70,Dashboard_Daten!$A$2:$A$70,$B$2,Dashboard_Daten!$C$2:$C$70,$B$3))) -> 1166095.5 | C11: =IF($B$7=0,"",IF($B$3="Gesamtportfolio",SUMIFS(Dashboard_Daten!$X$2:$X$70,Dashboard_Daten!$A$2:$A$70,$B$4),SUMIFS(Dashboard_Daten!$X$2:$X$70,Dashboard_Daten!$A$2:$A$70,$B$4,Dashboard_Daten!$C$2:$C$70,$B$3))) -> 1033260.2 | D11: =IF(OR(B11="",C11=""),"",B11-C11) -> 132835.3 | E11: =IF(OR(C11="",C11=0),"",D11/ABS(C11)) -> 0.12855939 | N11: EHAP-Projekt (Weihnachtsaktion)
A12: erweiterte Teilkosten | B12: =IF($B$6=0,"",IF($B$3="Gesamtportfolio",SUMIFS(Dashboard_Daten!$M$2:$M$70,Dashboard_Daten!$A$2:$A$70,$B$2),SUMIFS(Dashboard_Daten!$M$2:$M$70,Dashboard_Daten!$A$2:$A$70,$B$2,Dashboard_Daten!$C$2:$C$70,$B$3))) -> 882975.56 | C12: =IF($B$7=0,"",IF($B$3="Gesamtportfolio",SUMIFS(Dashboard_Daten!$M$2:$M$70,Dashboard_Daten!$A$2:$A$70,$B$4),SUMIFS(Dashboard_Daten!$M$2:$M$70,Dashboard_Daten!$A$2:$A$70,$B$4,Dashboard_Daten!$C$2:$C$70,$B$3))) -> 860047.36 | D12: =IF(OR(B12="",C12=""),"",B12-C12) -> 22928.2 | E12: =IF(OR(C12="",C12=0),"",D12/ABS(C12)) -> 0.02665923 | N12: Notunterkunft Ohlauer Straße
A13: KLR-Jahresmengen | B13: =IF($B$6=0,"",IF($B$3="Gesamtportfolio",SUMIFS(Dashboard_Daten!$R$2:$R$70,Dashboard_Daten!$A$2:$A$70,$B$2),SUMIFS(Dashboard_Daten!$R$2:$R$70,Dashboard_Daten!$A$2:$A$70,$B$2,Dashboard_Daten!$C$2:$C$70,$B$3))) -> 74368.333 | C13: {=IF($B$7=0,"",IF($B$3="Gesamtportfolio",SUMIFS(Dashboard_Daten!$R$2:$R$70,Dashboard_Daten!$A$2:$A$70,$B$4),SUMIFS(Dashboard_Daten!$R$2:$R$70,Dashboard_Daten!$A$2:$A$70,$B$4,Dashboard_Daten!$C$2:$C$70,$B$3)))} -> 72042 | D13: =IF(OR(B13="",C13=""),"",B13-C13) -> 2326.3333 | E13: =IF(OR(C13="",C13=0),"",D13/ABS(C13)) -> 0.032291349 | N13: Versorgung Obdachloser Menschen mit Lebensmitteln und Hygieneartikel
A14: Gesamt-Jahresmengen | B14: =IF($B$6=0,"",IF($B$3="Gesamtportfolio",SUMIFS(Dashboard_Daten!$O$2:$O$70,Dashboard_Daten!$A$2:$A$70,$B$2),SUMIFS(Dashboard_Daten!$O$2:$O$70,Dashboard_Daten!$A$2:$A$70,$B$2,Dashboard_Daten!$C$2:$C$70,$B$3))) -> 92171.19 | C14: =IF($B$7=0,"",IF($B$3="Gesamtportfolio",SUMIFS(Dashboard_Daten!$O$2:$O$70,Dashboard_Daten!$A$2:$A$70,$B$4),SUMIFS(Dashboard_Daten!$O$2:$O$70,Dashboard_Daten!$A$2:$A$70,$B$4,Dashboard_Daten!$C$2:$C$70,$B$3))) -> 96401 | D14: =IF(OR(B14="",C14=""),"",B14-C14) -> -4229.8095 | E14: =IF(OR(C14="",C14=0),"",D14/ABS(C14)) -> -0.043877237 | N14: Johanniter
A15: KLR-relevanter AfS-Anteil | B15: =IFERROR(B13/B14,"") -> 0.80685009 | C15: =IFERROR(C13/C14,"") -> 0.7473159 | D15: =IF(OR(B15="",C15=""),"",B15-C15) -> 0.059534191 | E15: =IF(D15="","",D15*100) -> 5.9534191 | N15: Warmlufthalle am Containerbahnhof
A16: Stückkosten | B16: =IFERROR(B12/B13,"") -> 11.873005 | C16: =IFERROR(C12/C13,"") -> 11.938138 | D16: =IF(OR(B16="",C16=""),"",B16-C16) -> -0.065133759 | E16: =IF(OR(C16="",C16=0),"",D16/ABS(C16)) -> -0.0054559394 | N16: Solidarisches Kreuzberg, Fest am 24.12.2022 für Wohnungslose
A17: Median | B17: =IF($B$6=0,"",(IF($B$6=0,"",IF($B$3="Gesamtportfolio",SUMIFS(Dashboard_Daten!$U$2:$U$70,Dashboard_Daten!$A$2:$A$70,$B$2),SUMIFS(Dashboard_Daten!$U$2:$U$70,Dashboard_Daten!$A$2:$A$70,$B$2,Dashboard_Daten!$C$2:$C$70,$B$3))))/$B$6) -> 15.68 | C17: {=IF($B$7=0,"",(IF($B$7=0,"",IF($B$3="Gesamtportfolio",SUMIFS(Dashboard_Daten!$U$2:$U$70,Dashboard_Daten!$A$2:$A$70,$B$4),SUMIFS(Dashboard_Daten!$U$2:$U$70,Dashboard_Daten!$A$2:$A$70,$B$4,Dashboard_Daten!$C$2:$C$70,$B$3))))/$B$7)} -> 14.342469 | D17: =IF(OR(B17="",C17=""),"",B17-C17) -> 1.3375307 | E17: =IF(OR(C17="",C17=0),"",D17/ABS(C17)) -> 0.093256657 | N17: Safe Place
A18: Zuwendung | B18: =IF($B$6=0,"",IF($B$3="Gesamtportfolio",SUMIFS(Dashboard_Daten!$D$2:$D$70,Dashboard_Daten!$A$2:$A$70,$B$2),SUMIFS(Dashboard_Daten!$D$2:$D$70,Dashboard_Daten!$A$2:$A$70,$B$2,Dashboard_Daten!$C$2:$C$70,$B$3))) -> 847782.56 | C18: =IF($B$7=0,"",IF($B$3="Gesamtportfolio",SUMIFS(Dashboard_Daten!$D$2:$D$70,Dashboard_Daten!$A$2:$A$70,$B$4),SUMIFS(Dashboard_Daten!$D$2:$D$70,Dashboard_Daten!$A$2:$A$70,$B$4,Dashboard_Daten!$C$2:$C$70,$B$3))) -> 810814.36 | D18: =IF(OR(B18="",C18=""),"",B18-C18) -> 36968.2 | E18: =IF(OR(C18="",C18=0),"",D18/ABS(C18)) -> 0.045593914
A19: IKT | B19: =IF($B$6=0,"",IF($B$3="Gesamtportfolio",SUMIFS(Dashboard_Daten!$K$2:$K$70,Dashboard_Daten!$A$2:$A$70,$B$2),SUMIFS(Dashboard_Daten!$K$2:$K$70,Dashboard_Daten!$A$2:$A$70,$B$2,Dashboard_Daten!$C$2:$C$70,$B$3))) -> 35193 | C19: =IF($B$7=0,"",IF($B$3="Gesamtportfolio",SUMIFS(Dashboard_Daten!$K$2:$K$70,Dashboard_Daten!$A$2:$A$70,$B$4),SUMIFS(Dashboard_Daten!$K$2:$K$70,Dashboard_Daten!$A$2:$A$70,$B$4,Dashboard_Daten!$C$2:$C$70,$B$3))) -> 49233 | D19: =IF(OR(B19="",C19=""),"",B19-C19) -> -14040 | E19: =IF(OR(C19="",C19=0),"",D19/ABS(C19)) -> -0.28517458
A20: Transferkosten | B20: =IF($B$6=0,"",IF($B$3="Gesamtportfolio",SUMIFS(Dashboard_Daten!$L$2:$L$70,Dashboard_Daten!$A$2:$A$70,$B$2),SUMIFS(Dashboard_Daten!$L$2:$L$70,Dashboard_Daten!$A$2:$A$70,$B$2,Dashboard_Daten!$C$2:$C$70,$B$3))) -> 0 | C20: =IF($B$7=0,"",IF($B$3="Gesamtportfolio",SUMIFS(Dashboard_Daten!$L$2:$L$70,Dashboard_Daten!$A$2:$A$70,$B$4),SUMIFS(Dashboard_Daten!$L$2:$L$70,Dashboard_Daten!$A$2:$A$70,$B$4,Dashboard_Daten!$C$2:$C$70,$B$3))) -> 0 | D20: =IF(OR(B20="",C20=""),"",B20-C20) -> 0 | E20: =IF(OR(C20="",C20=0),"",D20/ABS(C20))
A21: Projektkosten | B21: =IF($B$6=0,"",IF($B$3="Gesamtportfolio",SUMIFS(Dashboard_Daten!$H$2:$H$70,Dashboard_Daten!$A$2:$A$70,$B$2),SUMIFS(Dashboard_Daten!$H$2:$H$70,Dashboard_Daten!$A$2:$A$70,$B$2,Dashboard_Daten!$C$2:$C$70,$B$3))) -> 1187333 | C21: {=IF($B$7=0,"",IF($B$3="Gesamtportfolio",SUMIFS(Dashboard_Daten!$H$2:$H$70,Dashboard_Daten!$A$2:$A$70,$B$4),SUMIFS(Dashboard_Daten!$H$2:$H$70,Dashboard_Daten!$A$2:$A$70,$B$4,Dashboard_Daten!$C$2:$C$70,$B$3)))} -> 1691917.1 | D21: =IF(OR(B21="",C21=""),"",B21-C21) -> -504584.14 | E21: =IF(OR(C21="",C21=0),"",D21/ABS(C21)) -> -0.29823219
A22: Zuwendungsanteil | B22: =IFERROR(B18/B21,"") -> 0.71402259 | C22: =IFERROR(C18/C21,"") -> 0.47922818 | D22: =IF(OR(B22="",C22=""),"",B22-C22) -> 0.23479441 | E22: =IF(D22="","",D22*100) -> 23.479441
A23: Dritt-/Eigenmittelanteil | B23: =IFERROR((IF($B$6=0,"",IF($B$3="Gesamtportfolio",SUMIFS(Dashboard_Daten!$E$2:$E$70,Dashboard_Daten!$A$2:$A$70,$B$2)+SUMIFS(Dashboard_Daten!$F$2:$F$70,Dashboard_Daten!$A$2:$A$70,$B$2),SUMIFS(Dashboard_Daten!$E$2:$E$70,Dashboard_Daten!$A$2:$A$70,$B$2,Dashboard_Daten!$C$2:$C$70,$B$3)+SUMIFS(Dashboard_Daten!$F$2:$F$70,Dashboard_Daten!$A$2:$A$70,$B$2,Dashboard_Daten!$C$2:$C$70,$B$3))))/B21,"") -> 0.28597741 | C23: =IFERROR((IF($B$7=0,"",IF($B$3="Gesamtportfolio",SUMIFS(Dashboard_Daten!$E$2:$E$70,Dashboard_Daten!$A$2:$A$70,$B$4)+SUMIFS(Dashboard_Daten!$F$2:$F$70,Dashboard_Daten!$A$2:$A$70,$B$4),SUMIFS(Dashboard_Daten!$E$2:$E$70,Dashboard_Daten!$A$2:$A$70,$B$4,Dashboard_Daten!$C$2:$C$70,$B$3)+SUMIFS(Dashboard_Daten!$F$2:$F$70,Dashboard_Daten!$A$2:$A$70,$B$4,Dashboard_Daten!$C$2:$C$70,$B$3))))/C21,"") -> 0.52077182 | D23: =IF(OR(B23="",C23=""),"",B23-C23) -> -0.23479441 | E23: =IF(D23="","",D23*100) -> -23.479441
A24: Deckungsbeitrag je KLR-Menge | B24: =IF(OR(B16="",B17=""),"",B17-B16) -> 3.8069955 | C24: =IF(OR(C16="",C17=""),"",C17-C16) -> 2.404331 | D24: =IF(OR(B24="",C24=""),"",B24-C24) -> 1.4026645
A25: Jahresmengen laufend | B25: =IF($B$6=0,"",IF($B$3="Gesamtportfolio",SUMIFS(Dashboard_Daten!$N$2:$N$70,Dashboard_Daten!$A$2:$A$70,$B$2),SUMIFS(Dashboard_Daten!$N$2:$N$70,Dashboard_Daten!$A$2:$A$70,$B$2,Dashboard_Daten!$C$2:$C$70,$B$3))) -> 53822 | C25: {=IF($B$7=0,"",IF($B$3="Gesamtportfolio",SUMIFS(Dashboard_Daten!$N$2:$N$70,Dashboard_Daten!$A$2:$A$70,$B$4),SUMIFS(Dashboard_Daten!$N$2:$N$70,Dashboard_Daten!$A$2:$A$70,$B$4,Dashboard_Daten!$C$2:$C$70,$B$3)))} -> 96401 | D25: =IF(OR(B25="",C25=""),"",B25-C25) -> -42579 | E25: =IF(OR(C25="",C25=0),"",D25/ABS(C25)) -> -0.44168629
A26: KLR-Mengen laufend | B26: =IF($B$6=0,"",IF($B$3="Gesamtportfolio",SUMIFS(Dashboard_Daten!$Q$2:$Q$70,Dashboard_Daten!$A$2:$A$70,$B$2),SUMIFS(Dashboard_Daten!$Q$2:$Q$70,Dashboard_Daten!$A$2:$A$70,$B$2,Dashboard_Daten!$C$2:$C$70,$B$3))) -> 43437 | C26: =IF($B$7=0,"",IF($B$3="Gesamtportfolio",SUMIFS(Dashboard_Daten!$Q$2:$Q$70,Dashboard_Daten!$A$2:$A$70,$B$4),SUMIFS(Dashboard_Daten!$Q$2:$Q$70,Dashboard_Daten!$A$2:$A$70,$B$4,Dashboard_Daten!$C$2:$C$70,$B$3))) -> 70637.167 | D26: =IF(OR(B26="",C26=""),"",B26-C26) -> -27200.167 | E26: =IF(OR(C26="",C26=0),"",D26/ABS(C26)) -> -0.38506877
A27: KLR-Monat | B27: =IF($B$3="Gesamtportfolio","",IF(SUMIFS(Dashboard_Daten!$P$2:$P$70,Dashboard_Daten!$A$2:$A$70,$B$2,Dashboard_Daten!$C$2:$C$70,$B$3)=0,"",SUMIFS(Dashboard_Daten!$P$2:$P$70,Dashboard_Daten!$A$2:$A$70,$B$2,Dashboard_Daten!$C$2:$C$70,$B$3))) | C27: =IF($B$3="Gesamtportfolio","",IF(SUMIFS(Dashboard_Daten!$P$2:$P$70,Dashboard_Daten!$A$2:$A$70,$B$4,Dashboard_Daten!$C$2:$C$70,$B$3)=0,"",SUMIFS(Dashboard_Daten!$P$2:$P$70,Dashboard_Daten!$A$2:$A$70,$B$4,Dashboard_Daten!$C$2:$C$70,$B$3))) | D27: =IF(OR(B27="",C27=""),"",B27-C27)
A29: Treiber | B29: Beitrag zur Δ Saldo | C29: Betrag absolut
A30: Gesamtmengenwirkung | B30: =IF(OR(C14="",C15="",C17=""),"",(B14-C14)*C15*C17) -> -45336.601 | C30: =IF(B30="","",ABS(B30)) -> 45336.601
A31: Wirkung AfS-Anteil | B31: =IF(OR(B14="",B15="",C15="",C17=""),"",B14*(B15-C15)*C17) -> 78701.966 | C31: =IF(B31="","",ABS(B31)) -> 78701.966
A32: Medianwirkung | B32: =IF(OR(B13="",B17="",C17=""),"",B13*(B17-C17)) -> 99469.932 | C32: {=IF(B32="","",ABS(B32))} -> 99469.932
A33: Zuwendungswirkung | B33: =IF(OR(B18="",C18=""),"",-(B18-C18)) -> -36968.2 | C33: =IF(B33="","",ABS(B33)) -> 36968.2
A34: IKT-Wirkung | B34: =IF(OR(B19="",C19=""),"",-(B19-C19)) -> 14040 | C34: =IF(B34="","",ABS(B34)) -> 14040
A35: Transferkostenwirkung | B35: =IF(OR(B20="",C20=""),"",-(B20-C20)) -> 0 | C35: {=IF(B35="","",ABS(B35))} -> 0
A36: Summe Treiber | B36: =IF(COUNT(B30:B35)=0,"",SUM(B30:B35)) -> 109907.1
A37: Δ Refinanzierungssaldo | B37: =D10 -> 109907.1
A38: Restdifferenz | B38: =IF(OR(B36="",B37=""),"",IF(ABS(B37-B36)<0.01,0,B37-B36)) -> 0
A40: Größter Treiber | B40: =IF(COUNT(C30:C35)=0,"",INDEX(A30:A35,MATCH(MAX(C30:C35),C30:C35,0))) -> Medianwirkung | C40: =IF(B40="","",INDEX(B30:B35,MATCH(MAX(C30:C35),C30:C35,0))) -> 99469.932
A43: Projektliste / Portfolio-Ranking | B43: Saldo | C43: vorhanden | D43: Sortierwert
A44: Gesamtportfolio | J44: Projekt | K44: Refinanzierungssaldo | L44: Kurzlabel
...

Sheet Dashboard
A1: Finanzierungssteuerung – Produkt 80681
A2: Refinanzierungssaldo, Mengen- und Kostentreiber | Friedrichshain-Kreuzberg | 2021–2026
A4: Jahr | B4: 2026 | C4: Projekt | E4: Gesamtportfolio | G4: =IF(KPI!$B$5="Hochrechnung","Hochrechnung auf Basis der laufenden Mengen","Jahresabschlusswert") -> Hochrechnung auf Basis der laufenden Mengen
A6: Refinanzierungssaldo | E6: KLR-Jahresmengen | I6: Stückkosten je KLR-Menge | M6: Medianpreis je KLR-Menge | Q6: Erweiterte Teilkosten
A7: =KPI!B10 -> 283119.91 | E7: =KPI!B13 -> 74368.333 | I7: =KPI!B16 -> 11.873005 | M7: =KPI!B17 -> 15.68 | Q7: =KPI!B12 -> 882975.56
A9: Δ zum Vorjahr | B9: =KPI!D10 -> 109907.1 | E9: Δ zum Vorjahr | F9: =KPI!E13 -> 0.032291349 | I9: Δ zum Vorjahr | J9: =KPI!E16 -> -0.0054559394 | M9: Δ zum Vorjahr | N9: =KPI!D17 -> 1.3375307 | Q9: Δ zum Vorjahr | R9: =KPI!E12 -> 0.02665923
A10: ="Vorjahr "&KPI!$B$4 -> Vorjahr 2025 | B10: =KPI!C10 -> 173212.81 | E10: ="Vorjahr "&KPI!$B$4 -> Vorjahr 2025 | F10: =KPI!C13 -> 72042 | I10: ="Vorjahr "&KPI!$B$4 -> Vorjahr 2025 | J10: =KPI!C16 -> 11.938138 | M10: ="Vorjahr "&KPI!$B$4 -> Vorjahr 2025 | N10: =KPI!C17 -> 14.342469 | Q10: ="Vorjahr "&KPI!$B$4 -> Vorjahr 2025 | R10: =KPI!C12 -> 860047.36
A13: 1 | Refinanzierung: Wie entsteht der Saldo?
A14: Refinanzierungsertrag | G14: − | H14: Erweiterte Teilkosten | N14: = | O14: Refinanzierungssaldo
A15: =KPI!B11 -> 1166095.5 | H15: =KPI!B12 -> 882975.56 | O15: =KPI!B10 -> 283119.91
A18: KLR-Jahresmengen × Medianpreis | H18: Zuwendung + IKT + Transferkosten | O18: Ertrag − erweiterte Teilkosten
O21: Größter Treiber zum Vorjahr
O22: =KPI!B40 -> Medianwirkung
O25: =KPI!C40 -> 99469.932
O27: Beitrag zur Veränderung des Saldos
O29: Deckungsbeitrag je KLR-Menge
O30: =KPI!B24 -> 3.8069955
A35: 2 | Mengenpfad: Gesamtmengen × KLR-relevanter AfS-Anteil = KLR-Mengen
A37: Gesamt-Jahresmengen | G37: × | H37: KLR-relevanter AfS-Anteil | N37: = | O37: KLR-Jahresmengen
A38: =KPI!B14 -> 92171.19 | H38: =KPI!B15 -> 0.80685009 | O38: =KPI!B13 -> 74368.333
A41: ="Vorjahr "&KPI!$B$4 -> Vorjahr 2025 | B41: =KPI!C14 -> 96401 | H41: ="Vorjahr "&KPI!$B$4 -> Vorjahr 2025 | I41: =KPI!C15 -> 0.7473159 | O41: ="Vorjahr "&KPI!$B$4 -> Vorjahr 2025 | P41: =KPI!C13 -> 72042
A42: Δ zum Vorjahr | B42: =KPI!E14 -> -0.043877237 | H42: Δ zum Vorjahr | I42: =KPI!E15 -> 5.9534191 | O42: Δ zum Vorjahr | P42: =KPI!E13 -> 0.032291349
A44: Der KLR-relevante AfS-Anteil wird als KLR-Jahresmengen ÷ Gesamt-Jahresmengen berechnet. Für 2021–2024 werden die in der Quelle fehlenden Gesamt-Jahresmengen aus KLR-Jahresmengen und Zuwendungsanteil rekonstruiert.
A46: 3 | Kostenpfad: Zuwendung + IKT + Transferkosten = erweiterte Teilkosten
A48: Zuwendung | E48: + | F48: IKT | J48: + | K48: Transferkosten | O48: = | P48: Erweiterte Teilkosten
A49: =KPI!B18 -> 847782.56 | F49: =KPI!B19 -> 35193 | K49: =KPI!B20 -> 0 | P49: =KPI!B12 -> 882975.56
A52: ="Vorjahr "&KPI!$B$4 -> Vorjahr 2025 | B52: =KPI!C18 -> 810814.36 | F52: ="Vorjahr "&KPI!$B$4 -> Vorjahr 2025 | G52: =KPI!C19 -> 49233 | K52: ="Vorjahr "&KPI!$B$4 -> Vorjahr 2025 | L52: =KPI!C20 -> 0 | P52: ="Vorjahr "&KPI!$B$4 -> Vorjahr 2025 | Q52: =KPI!C12 -> 860047.36
A53: Δ zum Vorjahr | B53: =KPI!E18 -> 0.045593914 | F53: Δ zum Vorjahr | G53: =KPI!E19 -> -0.28517458 | K53: Δ zum Vorjahr | L53: =KPI!E20 | P53: Δ zum Vorjahr | Q53: =KPI!E12 -> 0.02665923
A56: 4 | Portfolio-Blick: Wo liegen die größten negativen Salden?
A57: Portfolio-Saldo | F57: Defizitprojekte | K57: Überschussprojekte | P57: Projekte insgesamt
A58: =KPI!B60 -> 283119.91 | F58: =KPI!B61 -> 2 | K58: =KPI!B62 -> 3 | P58: =KPI!B63 -> 5
N62: Projekt | R62: Saldo
N63: =IF(KPI!J45="","",KPI!J45) -> WoTa "Am Wassertor" | R63: =IF(KPI!K45="","",KPI!K45) -> -10179.63
N64: =IF(KPI!J46="","",KPI!J46) -> Medizinische Betreuung Obdachloser | R64: =IF(KPI!K46="","",KPI!K46) -> -5569.84
N65: =IF(KPI!J47="","",KPI!J47) | R65: =IF(KPI!K47="","",KPI!K47)
N66: =IF(KPI!J48="","",KPI!J48) | R66: =IF(KPI!K48="","",KPI!K48)
N67: =IF(KPI!J49="","",KPI!J49) | R67: =IF(KPI!K49="","",KPI!K49)
N68: =IF(KPI!J50="","",KPI!J50) | R68: =IF(KPI!K50="","",KPI!K50)
N70: Die Rangliste bleibt auf das ausgewählte Jahr bezogen. Für die Ursachenanalyse eines Projekts oben im Auswahlfeld das Projekt wählen.
A76: Leselogik: 2026 ist eine Hochrechnung auf Basis der laufenden Mengen; 2021–2025 sind Jahresabschlusswerte. Der Refinanzierungssaldo entspricht Refinanzierungsertrag minus erweiterte Teilkosten. Positive Treiberbeiträge verbessern, negative Beiträge belasten den Saldo.

Sheet Entwicklung
A1: ENTWICKLUNG 2021–2026 | PRODUKT 80-68-1
A2: Zeitliche Entwicklung der vier Steuerungsperspektiven · 2021–2025 Jahresabschluss · 2026 Hochrechnung
A4: Projektauswahl | B4: Gesamtportfolio | H4: Punkte 1–3 folgen der Auswahl. Punkt 4 bleibt ein unveränderter Portfolio-Blick.
A6: 1 | FINANZIELLE ENTWICKLUNG – Ertrag, Teilkosten und Saldo
A25: 2 | MENGENENTWICKLUNG – Gesamtmengen, KLR-Mengen und AfS-Anteil
A44: 3 | KOSTENPFAD – Zuwendung, IKT, Transferkosten und erweiterte Teilkosten
A63: 4 | PORTFOLIO-ENTWICKLUNG – Gesamtwirkung und Projektstruktur
A82: Einordnung: 2021–2025 basieren auf Jahresabschlüssen, 2026 ist eine Hochrechnung. Die Gesamt-Jahresmengen 2021–2024 wurden aus den vorliegenden Jahreswerten rekonstruiert. Projektjahre ohne Datensatz werden in den Diagrammen als Lücke dargestellt.

Sheet Dashboard_Daten
A1: Jahr | B1: Träger | C1: Projekt | D1: Zuwendung | E1: Drittmittel | F1: Eigenmittel | G1: sonstige Einnahmen | H1: Projektkosten (Quelle) | I1: Zuwendungsanteil | J1: Dritt-/Eigenmittelanteil | K1: IKT | L1: Transferkosten | M1: erweiterte Teilkosten | N1: Jahresmengen laufend | O1: Gesamt-Jahresmengen | P1: KLR-Monat | Q1: KLR-Mengen laufend | R1: KLR-Jahresmengen | S1: SOLL-Mengen | T1: Stückkosten | U1: Median | V1: Refinanzierungssaldo | W1: KLR-relevanter AfS-Anteil | X1: Refinanzierungsertrag | Y1: Datenstatus
A2: 2021 | B2: GEBEWO | C2: Medizinische Betreuung Obdachloser | D2: 20000 | E2: 236402.87 | F2: 13606 | G2: 0 | H2: 270008.87 | I2: =IFERROR(D2/H2,"") -> 0.074071641 | J2: =IFERROR((E2+F2)/H2,"") -> 0.92592836 | K2: 610.68054 | L2: 0 | M2: =D2+K2+L2 -> 20610.681 | O2: =IFERROR(R2/I2,"") -> 37558.234 | Q2: =IF(P2>0,R2*P2/12,R2) -> 2782 | R2: 2782 | S2: =IFERROR(M2/U2,"") -> 1512.2643 | T2: =IFERROR(M2/R2,"") -> 7.4085839 | U2: 13.62902 | V2: =IFERROR(X2-M2,"") -> 17305.253 | W2: =IFERROR(R2/O2,"") -> 0.074071641 | X2: =IFERROR(R2*U2,"") -> 37915.933 | Y2: =IF(A2=MAX($A$2:$A$47),"Hochrechnung","Jahresabschluss") -> Jahresabschluss
A3: 2021 | B3: KG St.Thomas | C3: Café Krause | D3: 12556 | E3: 0 | F3: 0 | G3: 0 | H3: 12556 | I3: =IFERROR(D3/H3,"") -> 1 | J3: =IFERROR((E3+F3)/H3,"") -> 0 | K3: 383.38525 | L3: 0 | M3: =D3+K3+L3 -> 12939.385 | O3: =IFERROR(R3/I3,"") -> 838 | Q3: =IF(P3>0,R3*P3/12,R3) -> 838 | R3: 838 | S3: =IFERROR(M3/U3,"") -> 949.39955 | T3: =IFERROR(M3/R3,"") -> 15.440794 | U3: 13.62902 | V3: =IFERROR(X3-M3,"") -> -1518.2667 | W3: =IFERROR(R3/O3,"") -> 1 | X3: =IFERROR(R3*U3,"") -> 11421.119 | Y3: =IF(A3=MAX($A$2:$A$47),"Hochrechnung","Jahresabschluss") -> Jahresabschluss
A4: 2021 | B4: Diakonie | C4: WoTa "Am Wassertor" | D4: 200250 | E4: 10000 | F4: 3000 | G4: 0 | H4: 213250 | I4: =IFERROR(D4/H4,"") -> 0.93903869 | J4: =IFERROR((E4+F4)/H4,"") -> 0.060961313 | K4: 6114.4389 | L4: 0 | M4: =D4+K4+L4 -> 206364.44 | O4: =IFERROR(R4/I4,"") -> 16619.124 | Q4: =IF(P4>0,R4*P4/12,R4) -> 15606 | R4: 15606 | S4: =IFERROR(M4/U4,"") -> 15141.547 | T4: =IFERROR(M4/R4,"") -> 13.223404 | U4: 13.62902 | V4: =IFERROR(X4-M4,"") -> 6330.0439 | W4: =IFERROR(R4/O4,"") -> 0.93903869 | X4: =IFERROR(R4*U4,"") -> 212694.48 | Y4: =IF(A4=MAX($A$2:$A$47),"Hochrechnung","Jahresabschluss") -> Jahresabschluss
A5: 2021 | B5: Diakonie | C5: EHAP-Projekt | D5: 18238.33 | E5: 346528.22 | F5: 0 | G5: 0 | H5: 364766.55 | I5: =IFERROR(D5/H5,"") -> 0.050000007 | J5: =IFERROR((E5+F5)/H5,"") -> 0.94999999 | K5: 556.88966 | L5: 0 | M5: =D5+K5+L5 -> 18795.22 | O5: =IFERROR(R5/I5,"") -> 719.9999 | Q5: =IF(P5>0,R5*P5/12,R5) -> 36 | R5: 36 | S5: =IFERROR(M5/U5,"") -> 1379.0588 | T5: =IFERROR(M5/R5,"") -> 522.08944 | U5: 13.62902 | V5: =IFERROR(X5-M5,"") -> -18304.575 | W5: =IFERROR(R5/O5,"") -> 0.050000007 | X5: =IFERROR(R5*U5,"") -> 490.64471 | Y5: =IF(A5=MAX($A$2:$A$47),"Hochrechnung","Jahresabschluss") -> Jahresabschluss
A6: 2021 | B6: AWO | C6: WoTa Kiez Cafe | D6: 200250 | E6: 0 | F6: 0 | G6: 0 | H6: 200250 | I6: =IFERROR(D6/H6,"") -> 1 | J6: =IFERROR((E6+F6)/H6,"") -> 0 | K6: 6114.4389 | L6: 0 | M6: =D6+K6+L6 -> 206364.44 | O6: =IFERROR(R6/I6,"") -> 15449 | Q6: =IF(P6>0,R6*P6/12,R6) -> 15449 | R6: 15449 | S6: =IFERROR(M6/U6,"") -> 15141.547 | T6: =IFERROR(M6/R6,"") -> 13.357786 | U6: 13.62902 | V6: =IFERROR(X6-M6,"") -> 4190.2878 | W6: =IFERROR(R6/O6,"") -> 1 | X6: =IFERROR(R6*U6,"") -> 210554.73 | Y6: =IF(A6=MAX($A$2:$A$47),"Hochrechnung","Jahresabschluss") -> Jahresabschluss
A7: 2021 | B7: Bürgerhilfe e.v | C7: WoTa Bürgerhilfe | D7: 184072 | E7: 0 | F7: 0 | G7: 0 | H7: 184072 | I7: =IFERROR(D7/H7,"") -> 1 | J7: =IFERROR((E7+F7)/H7,"") -> 0 | K7: 5620.4594 | L7: 0 | M7: =D7+K7+L7 -> 189692.46 | O7: =IFERROR(R7/I7,"") -> 14169 | Q7: =IF(P7>0,R7*P7/12,R7) -> 14169 | R7: 14169 | S7: =IFERROR(M7/U7,"") -> 13918.276 | T7: =IFERROR(M7/R7,"") -> 13.387851 | U7: 13.62902 | V7: =IFERROR(X7-M7,"") -> 3417.122 | W7: =IFERROR(R7/O7,"") -> 1 | X7: =IFERROR(R7*U7,"") -> 193109.58 | Y7: =IF(A7=MAX($A$2:$A$47),"Hochrechnung","Jahresabschluss") -> Jahresabschluss
A8: 2021 | B8: RAA Berlin e.V. | C8: Sprachmittler für Bewohner der Str.d.Pariser Kommune | D8: 20000 | E8: 0 | F8: 0 | G8: 0 | H8: 20000 | I8: =IFERROR(D8/H8,"") -> 1 | J8: =IFERROR((E8+F8)/H8,"") -> 0 | K8: 610.68054 | L8: 0 | M8: =D8+K8+L8 -> 20610.681 | O8: =IFERROR(R8/I8,"") -> 307 | Q8: =IF(P8>0,R8*P8/12,R8) -> 307 | R8: 307 | S8: =IFERROR(M8/U8,"") -> 1512.2643 | T8: =IFERROR(M8/R8,"") -> 67.135767 | U8: 13.62902 | V8: =IFERROR(X8-M8,"") -> -16426.571 | W8: =IFERROR(R8/O8,"") -> 1 | X8: =IFERROR(R8*U8,"") -> 4184.1091 | Y8: =IF(A8=MAX($A$2:$A$47),"Hochrechnung","Jahresabschluss") -> Jahresabschluss
A9: 2021 | B9: Neue Chance Berlin | C9: Weihnachtsfeier für Wohnungslose Männer | D9: 900 | E9: 0 | F9: 0 | G9: 0 | H9: 900 | I9: =IFERROR(D9/H9,"") -> 1 | J9: =IFERROR((E9+F9)/H9,"") -> 0 | K9: 27.480624 | L9: 0 | M9: =D9+K9+L9 -> 927.48062 | O9: =IFERROR(R9/I9,"") -> 45 | Q9: =IF(P9>0,R9*P9/12,R9) -> 45 | R9: 45 | S9: =IFERROR(M9/U9,"") -> 68.051895 | T9: =IFERROR(M9/R9,"") -> 20.610681 | U9: 13.62902 | V9: =IFERROR(X9-M9,"") -> -314.17473 | W9: =IFERROR(R9/O9,"") -> 1 | X9: =IFERROR(R9*U9,"") -> 613.30589 | Y9: =IF(A9=MAX($A$2:$A$47),"Hochrechnung","Jahresabschluss") -> Jahresabschluss
A10: 2021 | B10: EHAP-Projekt | C10: EHAP-Projekt (Weihnachtsaktion) | D10: 1500 | E10: 0 | F10: 0 | G10: 0 | H10: 1500 | I10: =IFERROR(D10/H10,"") -> 1 | J10: =IFERROR((E10+F10)/H10,"") -> 0 | K10: 45.801041 | L10: 0 | M10: =D10+K10+L10 -> 1545.801 | O10: =IFERROR(R10/I10,"") -> 127 | Q10: =IF(P10>0,R10*P10/12,R10) -> 127 | R10: 127 | S10: =IFERROR(M10/U10,"") -> 113.41983 | T10: =IFERROR(M10/R10,"") -> 12.171662 | U10: 13.62902 | V10: =IFERROR(X10-M10,"") -> 185.08447 | W10: =IFERROR(R10/O10,"") -> 1 | X10: =IFERROR(R10*U10,"") -> 1730.8855 | Y10: =IF(A10=MAX($A$2:$A$47),"Hochrechnung","Jahresabschluss") -> Jahresabschluss
A11: 2021 | B11: Johanniter | C11: Notunterkunft Ohlauer Straße | D11: 6726 | E11: 0 | F11: 0 | G11: 0 | H11: 6726 | I11: =IFERROR(D11/H11,"") -> 1 | J11: =IFERROR((E11+F11)/H11,"") -> 0 | K11: 205.37187 | L11: 0 | M11: =D11+K11+L11 -> 6931.3719 | O11: =IFERROR(R11/I11,"") -> 159 | Q11: =IF(P11>0,R11*P11/12,R11) -> 159 | R11: 159 | S11: =IFERROR(M11/U11,"") -> 508.5745 | T11: =IFERROR(M11/R11,"") -> 43.593534 | U11: 13.62902 | V11: =IFERROR(X11-M11,"") -> -4764.3577 | W11: =IFERROR(R11/O11,"") -> 1 | X11: =IFERROR(R11*U11,"") -> 2167.0141 | Y11: =IF(A11=MAX($A$2:$A$47),"Hochrechnung","Jahresabschluss") -> Jahresabschluss
A12: 2022 | B12: GEBEWO | C12: Medizinische Betreuung Obdachloser | D12: 20000 | E12: 234785 | F12: 13606 | G12: 0 | H12: 268391 | I12: =IFERROR(D12/H12,"") -> 0.074518147 | J12: =IFERROR((E12+F12)/H12,"") -> 0.92548185 | K12: 1131.9019 | L12: 0 | M12: =D12+K12+L12 -> 21131.902 | O12: =IFERROR(R12/I12,"") -> 48538.512 | Q12: =IF(P12>0,R12*P12/12,R12) -> 3617 | R12: 3617 | S12: =IFERROR(M12/U12,"") -> 1557.9682 | T12: =IFERROR(M12/R12,"") -> 5.8423837 | U12: 13.563757 | V12: =IFERROR(X12-M12,"") -> 27928.206 | W12: =IFERROR(R12/O12,"") -> 0.074518147 | X12: =IFERROR(R12*U12,"") -> 49060.108 | Y12: =IF(A12=MAX($A$2:$A$47),"Hochrechnung","Jahresabschluss") -> Jahresabschluss
A13: 2022 | B13: KG St.Thomas | C13: Café Krause | D13: 7446 | E13: 0 | F13: 0 | G13: 0 | H13: 7446 | I13: =IFERROR(D13/H13,"") -> 1 | J13: =IFERROR((E13+F13)/H13,"") -> 0 | K13: 421.40709 | L13: 0 | M13: =D13+K13+L13 -> 7867.4071 | O13: =IFERROR(R13/I13,"") -> 1078 | Q13: =IF(P13>0,R13*P13/12,R13) -> 1078 | R13: 1078 | S13: =IFERROR(M13/U13,"") -> 580.03157 | T13: =IFERROR(M13/R13,"") -> 7.2981513 | U13: 13.563757 | V13: =IFERROR(X13-M13,"") -> 6754.3227 | W13: =IFERROR(R13/O13,"") -> 1 | X13: =IFERROR(R13*U13,"") -> 14621.73 | Y13: =IF(A13=MAX($A$2:$A$47),"Hochrechnung","Jahresabschluss") -> Jahresabschluss
... A35: 2024 | B35: Ev. KG Kreuzberg | C35: Café Krause | D35: 8896 | E35: 0 | F35: 0 | G35: 0 | H35: 8896 | I35: =IFERROR(D35/H35,"") -> 1 | J35: =IFERROR((E35+F35)/H35,"") -> 0 | K35: 273 | L35: 0 | M35: =D35+K35+L35 -> 9169 | O35: =IFERROR(R35/I35,"") -> 1227 | Q35: =IF(P35>0,R35*P35/12,R35) -> 1227 | R35: 1227 | S35: =IFERROR(M35/U35,"") -> 631.47383 | T35: =IFERROR(M35/R35,"") -> 7.4726976 | U35: 14.52 | V35: =IFERROR(X35-M35,"") -> 8647.04 | W35: =IFERROR(R35/O35,"") -> 1 | X35: =IFERROR(R35*U35,"") -> 17816.04 | Y35: =IF(A35=MAX($A$2:$A$47),"Hochrechnung","Jahresabschluss") -> Jahresabschluss
A36: 2025 | B36: GEBEWO | C36: Medizinische Betreuung Obdachloser | D36: 20000 | E36: 296618.04 | F36: 13606 | G36: 0 | H36: 330224.04 | I36: =IFERROR(D36/H36,"") -> 0.060564943 | J36: =IFERROR((E36+F36)/H36,"") -> 0.93943506 | K36: 1214 | L36: 0 | M36: =D36+K36+L36 -> 21214 | N36: 25022 | O36: 25022 | P36: 12 | Q36: =IF(P36>0,R36*P36/12,R36) -> 1528 | R36: 1528 | S36: =IFERROR(M36/U36,"") -> 1479.1037 | T36: =IFERROR(M36/R36,"") -> 13.883508 | U36: 14.342469 | V36: =IFERROR(X36-M36,"") -> 701.29303 | W36: =IFERROR(R36/O36,"") -> 0.061066262 | X36: =IFERROR(R36*U36,"") -> 21915.293 | Y36: =IF(A36=MAX($A$2:$A$47),"Hochrechnung","Jahresabschluss") -> Jahresabschluss
A37: 2025 | B37: Diakonie | C37: WoTa "Am Wassertor" | D37: 279075.55 | E37: 0 | F37: 5000 | G37: 0 | H37: 284075.55 | I37: =IFERROR(D37/H37,"") -> 0.98239905 | J37: =IFERROR((E37+F37)/H37,"") -> 0.017600952 | K37: 16946 | L37: 0 | M37: =D37+K37+L37 -> 296021.55 | N37: 17282 | O37: 17282 | P37: 12 | Q37: =IF(P37>0,R37*P37/12,R37) -> 16989 | R37: 16989 | S37: =IFERROR(M37/U37,"") -> 20639.511 | T37: =IFERROR(M37/R37,"") -> 17.424307 | U37: 14.342469 | V37: =IFERROR(X37-M37,"") -> -52357.34 | W37: =IFERROR(R37/O37,"") -> 0.98304594 | X37: =IFERROR(R37*U37,"") -> 243664.21 | Y37: =IF(A37=MAX($A$2:$A$47),"Hochrechnung","Jahresabschluss") -> Jahresabschluss
A38: 2025 | B38: Diakonie | C38: EHAP-Projekt | D38: 14827 | E38: 563038.7 | F38: 0 | G38: 0 | H38: 577865.7 | I38: =IFERROR(D38/H38,"") -> 0.025658211 | J38: =IFERROR((E38+F38)/H38,"") -> 0.97434179 | K38: 900 | L38: 0 | M38: =D38+K38+L38 -> 15727 | N38: 316 | O38: 316 | P38: 6 | Q38: =IF(P38>0,R38*P38/12,R38) -> 6 | R38: 12 | S38: =IFERROR(M38/U38,"") -> 1096.5336 | T38: =IFERROR(M38/R38,"") -> 1310.5833 | U38: 14.342469 | V38: =IFERROR(X38-M38,"") -> -15554.89 | W38: =IFERROR(R38/O38,"") -> 0.037974684 | X38: =IFERROR(R38*U38,"") -> 172.10963 | Y38: =IF(A38=MAX($A$2:$A$47),"Hochrechnung","Jahresabschluss") -> Jahresabschluss
A39: 2025 | B39: AWO | C39: WoTa Kiez Cafe | D39: 255696.11 | E39: 0 | F39: 840 | G39: 0 | H39: 256536.11 | I39: =IFERROR(D39/H39,"") -> 0.99672561 | J39: =IFERROR((E39+F39)/H39,"") -> 0.0032743928 | K39: 15526 | L39: 0 | M39: =D39+K39+L39 -> 271222.11 | N39: 29143 | O39: 29143 | P39: 12 | Q39: =IF(P39>0,R39*P39/12,R39) -> 29058 | R39: 29058 | S39: =IFERROR(M39/U39,"") -> 18910.419 | T39: =IFERROR(M39/R39,"") -> 9.3338189 | U39: 14.342469 | V39: =IFERROR(X39-M39,"") -> 145541.36 | W39: =IFERROR(R39/O39,"") -> 0.99708335 | X39: =IFERROR(R39*U39,"") -> 416763.47 | Y39: =IF(A39=MAX($A$2:$A$47),"Hochrechnung","Jahresabschluss") -> Jahresabschluss
A40: 2025 | B40: Bürgerhilfe e.v | C40: WoTa Bürgerhilfe | D40: 209334 | E40: 0 | F40: 2000 | G40: 0 | H40: 211334 | I40: =IFERROR(D40/H40,"") -> 0.99053631 | J40: =IFERROR((E40+F40)/H40,"") -> 0.0094636925 | K40: 12711 | L40: 0 | M40: =D40+K40+L40 -> 222045 | N40: 20445 | O40: 20445 | P40: 12 | Q40: =IF(P40>0,R40*P40/12,R40) -> 20262 | R40: 20262 | S40: =IFERROR(M40/U40,"") -> 15481.644 | T40: =IFERROR(M40/R40,"") -> 10.958691 | U40: 14.342469 | V40: =IFERROR(X40-M40,"") -> 68562.112 | W40: =IFERROR(R40/O40,"") -> 0.99104916 | X40: =IFERROR(R40*U40,"") -> 290607.11 | Y40: =IF(A40=MAX($A$2:$A$47),"Hochrechnung","Jahresabschluss") -> Jahresabschluss
A41: 2025 | B41: Berliner Stadtmission e.V. | C41: Safe Place | D41: 10000 | E41: 0 | F41: 0 | G41: 0 | H41: 10000 | I41: =IFERROR(D41/H41,"") -> 1 | J41: =IFERROR((E41+F41)/H41,"") -> 0 | K41: 607 | L41: 0 | M41: =D41+K41+L41 -> 10607 | N41: 1795 | O41: 1795 | P41: 12 | Q41: =IF(P41>0,R41*P41/12,R41) -> 1795 | R41: 1795 | S41: =IFERROR(M41/U41,"") -> 739.55187 | T41: =IFERROR(M41/R41,"") -> 5.9091922 | U41: 14.342469 | V41: =IFERROR(X41-M41,"") -> 15137.732 | W41: =IFERROR(R41/O41,"") -> 1 | X41: =IFERROR(R41*U41,"") -> 25744.732 | Y41: =IF(A41=MAX($A$2:$A$47),"Hochrechnung","Jahresabschluss") -> Jahresabschluss
A42: 2025 | B42: Ev. KG Kreuzberg | C42: Café Krause | D42: 21881.7 | E42: 0 | F42: 0 | G42: 0 | H42: 21881.7 | I42: =IFERROR(D42/H42,"") -> 1 | J42: =IFERROR((E42+F42)/H42,"") -> 0 | K42: 1329 | L42: 0 | M42: =D42+K42+L42 -> 23210.7 | N42: 2398 | O42: 2398 | P42: 5 | Q42: =IF(P42>0,R42*P42/12,R42) -> 999.16667 | R42: 2398 | S42: =IFERROR(M42/U42,"") -> 1618.3197 | T42: =IFERROR(M42/R42,"") -> 9.679191 | U42: 14.342469 | V42: =IFERROR(X42-M42,"") -> 11182.541 | W42: =IFERROR(R42/O42,"") -> 1 | X42: =IFERROR(R42*U42,"") -> 34393.241 | Y42: =IF(A42=MAX($A$2:$A$47),"Hochrechnung","Jahresabschluss") -> Jahresabschluss
A43: 2026 | B43: GEBEWO | C43: Medizinische Betreuung Obdachloser | D43: 20000 | E43: 241991.57 | F43: 69833.83 | G43: 0 | H43: =SUM(Tbl_Dashboard_Daten[[#This Row],[Zuwendung]:[sonstige Einnahmen]]) -> 331825.4 | I43: =IFERROR(D43/H43,"") -> 0.060272661 | J43: =IFERROR((E43+F43)/H43,"") -> 0.93972734 | K43: 1214 | L43: 0 | M43: =D43+K43+L43 -> 21214 | N43: ='[1]Zahlungen u. Mengen'!$S$223 -> 9520 | O43: =Tbl_Dashboard_Daten[[#This Row],[Jahresmengen laufend]]/Tbl_Dashboard_Daten[[#This Row],[KLR-Monat]]*12 -> 16320 | P43: =COUNT('[1]Zahlungen u. Mengen'!$P$211:$P$222) -> 7 | Q43: ='[1]Zahlungen u. Mengen'!$W$223 -> 582 | R43: =SUM(Tbl_Dashboard_Daten[[#This Row],[KLR-Mengen laufend]]/Tbl_Dashboard_Daten[[#This Row],[KLR-Monat]]*12) -> 997.71429 | S43: =IFERROR(M43/U43,"") -> 1352.9337 | T43: =IFERROR(M43/R43,"") -> 21.2626 | U43: 15.68 | V43: =IFERROR(X43-M43,"") -> -5569.84 | W43: =IFERROR(R43/O43,"") -> 0.061134454 | X43: =IFERROR(R43*U43,"") -> 15644.16 | Y43: =IF(A43=MAX($A$2:$A$47),"Hochrechnung","Jahresabschluss") -> Hochrechnung
A44: 2026 | B44: EJF gAG | C44: WoTa "Am Wassertor" | D44: 279075.55 | E44: 0 | F44: 5000 | G44: 0 | H44: =SUM(Tbl_Dashboard_Daten[[#This Row],[Zuwendung]:[sonstige Einnahmen]]) -> 284075.55 | I44: =IFERROR(D44/H44,"") -> 0.98239905 | J44: =IFERROR((E44+F44)/H44,"") -> 0.017600952 | K44: 16946 | L44: 0 | M44: =D44+K44+L44 -> 296021.55 | N44: ='[1]Zahlungen u. Mengen'!$S$210 -> 10813 | O44: =Tbl_Dashboard_Daten[[#This Row],[Jahresmengen laufend]]/Tbl_Dashboard_Daten[[#This Row],[KLR-Monat]]*12 -> 18536.571 | P44: =COUNT('[1]Zahlungen u. Mengen'!$P$198:$P$209) -> 7 | Q44: ='[1]Zahlungen u. Mengen'!$W$210 -> 10634 | R44: =SUM(Tbl_Dashboard_Daten[[#This Row],[KLR-Mengen laufend]]/Tbl_Dashboard_Daten[[#This Row],[KLR-Monat]]*12) -> 18229.714 | S44: =IFERROR(M44/U44,"") -> 18878.925 | T44: =IFERROR(M44/R44,"") -> 16.238409 | U44: 15.68 | V44: =IFERROR(X44-M44,"") -> -10179.63 | W44: =IFERROR(R44/O44,"") -> 0.98344585 | X44: =IFERROR(R44*U44,"") -> 285841.92 | Y44: =IF(A44=MAX($A$2:$A$47),"Hochrechnung","Jahresabschluss") -> Hochrechnung
A45: 2026 | B45: AWO | C45: WoTa Kiez Cafe | D45: 307259.9 | E45: 0 | F45: 840 | G45: 0 | H45: =SUM(Tbl_Dashboard_Daten[[#This Row],[Zuwendung]:[sonstige Einnahmen]]) -> 308099.9 | I45: =IFERROR(D45/H45,"") -> 0.99727361 | J45: =IFERROR((E45+F45)/H45,"") -> 0.0027263884 | K45: 900 | L45: 0 | M45: =D45+K45+L45 -> 308159.9 | N45: ='[1]Zahlungen u. Mengen'!$S$184 -> 17894 | O45: =Tbl_Dashboard_Daten[[#This Row],[Jahresmengen laufend]]/Tbl_Dashboard_Daten[[#This Row],[KLR-Monat]]*12 -> 30675.429 | P45: =COUNT('[1]Zahlungen u. Mengen'!$P$172:$P$183) -> 7 | Q45: ='[1]Zahlungen u. Mengen'!$W$184 -> 17852 | R45: =SUM(Tbl_Dashboard_Daten[[#This Row],[KLR-Mengen laufend]]/Tbl_Dashboard_Daten[[#This Row],[KLR-Monat]]*12) -> 30603.429 | S45: =IFERROR(M45/U45,"") -> 19653.055 | T45: =IFERROR(M45/R45,"") -> 10.069457 | U45: 15.68 | V45: =IFERROR(X45-M45,"") -> 171701.86 | W45: =IFERROR(R45/O45,"") -> 0.99765284 | X45: =IFERROR(R45*U45,"") -> 479861.76 | Y45: =IF(A45=MAX($A$2:$A$47),"Hochrechnung","Jahresabschluss") -> Hochrechnung
A46: 2026 | B46: Bürgerhilfe e.v | C46: WoTa Bürgerhilfe | D46: 219165.41 | E46: 19885 | F46: 2000 | G46: 0 | H46: =SUM(Tbl_Dashboard_Daten[[#This Row],[Zuwendung]:[sonstige Einnahmen]]) -> 241050.41 | I46: =IFERROR(D46/H46,"") -> 0.90920986 | J46: =IFERROR((E46+F46)/H46,"") -> 0.090790138 | K46: 15526 | L46: 0 | M46: =D46+K46+L46 -> 234691.41 | N46: ='[1]Zahlungen u. Mengen'!$S$197 -> 13598 | O46: =Tbl_Dashboard_Daten[[#This Row],[Jahresmengen laufend]]/Tbl_Dashboard_Daten[[#This Row],[KLR-Monat]]*12 -> 23310.857 | P46: =COUNT('[1]Zahlungen u. Mengen'!$P$185:$P$196) -> 7 | Q46: ='[1]Zahlungen u. Mengen'!$W$197 -> 12372 | R46: =SUM(Tbl_Dashboard_Daten[[#This Row],[KLR-Mengen laufend]]/Tbl_Dashboard_Daten[[#This Row],[KLR-Monat]]*12) -> 21209.143 | S46: =IFERROR(M46/U46,"") -> 14967.564 | T46: =IFERROR(M46/R46,"") -> 11.065577 | U46: 15.68 | V46: =IFERROR(X46-M46,"") -> 97867.95 | W46: =IFERROR(R46/O46,"") -> 0.90983968 | X46: =IFERROR(R46*U46,"") -> 332559.36 | Y46: =IF(A46=MAX($A$2:$A$47),"Hochrechnung","Jahresabschluss") -> Hochrechnung
A47: 2026 | B47: Ev. KG Kreuzberg | C47: Café Krause | D47: 22281.7 | E47: 0 | F47: 0 | G47: 0 | H47: =SUM(Tbl_Dashboard_Daten[[#This Row],[Zuwendung]:[sonstige Einnahmen]]) -> 22281.7 | I47: =IFERROR(D47/H47,"") -> 1 | J47: =IFERROR((E47+F47)/H47,"") -> 0 | K47: 607 | L47: 0 | M47: =D47+K47+L47 -> 22888.7 | N47: ='[1]Zahlungen u. Mengen'!$S$236 -> 1997 | O47: =Tbl_Dashboard_Daten[[#This Row],[Jahresmengen laufend]]/Tbl_Dashboard_Daten[[#This Row],[KLR-Monat]]*5 -> 3328.3333 | P47: =COUNT('[1]Zahlungen u. Mengen'!$P$224:$P$235) -> 3 | Q47: ='[1]Zahlungen u. Mengen'!$W$236 -> 1997 | R47: =SUM(Tbl_Dashboard_Daten[[#This Row],[KLR-Mengen laufend]]/Tbl_Dashboard_Daten[[#This Row],[KLR-Monat]]*5) -> 3328.3333 | S47: =IFERROR(M47/U47,"") -> 1459.7385 | T47: =IFERROR(M47/R47,"") -> 6.8769254 | U47: 15.68 | V47: =IFERROR(X47-M47,"") -> 29299.567 | W47: =IFERROR(R47/O47,"") -> 1 | X47: =IFERROR(R47*U47,"") -> 52188.267 | Y47: =IF(A47=MAX($A$2:$A$47),"Hochrechnung","Jahresabschluss") -> Hochrechnung
I48: =IFERROR(D48/H48,"") | J48: =IFERROR((E48+F48)/H48,"") | S48: =IFERROR(M48/U48,"") | T48: =IFERROR(M48/R48,"") | V48: =IFERROR(X48-M48,"") -> 0 | W48: =IFERROR(R48/#REF!,"") | X48: =IFERROR(R48*U48,"") -> 0
I49: =IFERROR(D49/H49,"") | J49: =IFERROR((E49+F49)/H49,"") | S49: =IFERROR(M49/U49,"") | T49: =IFERROR(M49/R49,"") | V49: =IFERROR(X49-M49,"") -> 0 | W49: =IFERROR(R49/O49,"") | X49: =IFERROR(R49*U49,"") -> 0
I50: =IFERROR(D50/H50,"") | J50: =IFERROR((E50+F50)/H50,"") | S50: =IFERROR(M50/U50,"") | T50: =IFERROR(M50/R50,"") | V50: =IFERROR(X50-M50,"") -> 0 | W50: =IFERROR(R50/O50,"") | X50: =IFERROR(R50*U50,"") -> 0
I51: =IFERROR(D51/H51,"") | J51: =IFERROR((E51+F51)/H51,"") | S51: =IFERROR(M51/U51,"") | T51: =IFERROR(M51/R51,"") | V51: =IFERROR(X51-M51,"") -> 0 | W51: =IFERROR(R51/O51,"") | X51: =IFERROR(R51*U51,"") -> 0
I52: =IFERROR(D52/H52,"") | J52: =IFERROR((E52+F52)/H52,"") | S52: =IFERROR(M52/U52,"") | T52: =IFERROR(M52/R52,"") | V52: =IFERROR(X52-M52,"") -> 0 | W52: =IFERROR(R52/O52,"") | X52: =IFERROR(R52*U52,"") -> 0
I53: =IFERROR(D53/H53,"") | J53: =IFERROR((E53+F53)/H53,"") | S53: =IFERROR(M53/U53,"") | T53: =IFERROR(M53/R53,"") | V53: =IFERROR(X53-M53,"") -> 0 | W53: =IFERROR(R53/O53,"") | X53: =IFERROR(R53*U53,"") -> 0
I54: =IFERROR(D54/H54,"") | J54: =IFERROR((E54+F54)/H54,"") | S54: =IFERROR(M54/U54,"") | T54: =IFERROR(M54/R54,"") | V54: =IFERROR(X54-M54,"") -> 0 | W54: =IFERROR(R54/O54,"") | X54: =IFERROR(R54*U54,"") -> 0
I55: =IFERROR(D55/H55,"") | J55: =IFERROR((E55+F55)/H55,"") | S55: =IFERROR(M55/U55,"") | T55: =IFERROR(M55/R55,"") | V55: =IFERROR(X55-M55,"") -> 0 | W55: =IFERROR(R55/O55,"") | X55: =IFERROR(R55*U55,"") -> 0
I56: =IFERROR(D56/H56,"") | J56: =IFERROR((E56+F56)/H56,"") | S56: =IFERROR(M56/U56,"") | T56: =IFERROR(M56/R56,"") | V56: =IFERROR(X56-M56,"") -> 0 | W56: =IFERROR(R56/O56,"") | X56: =IFERROR(R56*U56,"") -> 0
I57: =IFERROR(D57/H57,"") | J57: =IFERROR((E57+F57)/H57,"") | S57: =IFERROR(M57/U57,"") | T57: =IFERROR(M57/R57,"") | V57: =IFERROR(X57-M57,"") -> 0 | W57: =IFERROR(R57/O57,"") | X57: =IFERROR(R57*U57,"") -> 0
I58: =IFERROR(D58/H58,"") | J58: =IFERROR((E58+F58)/H58,"") | S58: =IFERROR(M58/U58,"") | T58: =IFERROR(M58/R58,"") | V58: =IFERROR(X58-M58,"") -> 0 | W58: =IFERROR(R58/O58,"") | X58: =IFERROR(R58*U58,"") -> 0
I59: =IFERROR(D59/H59,"") | J59: =IFERROR((E59+F59)/H59,"") | S59: =IFERROR(M59/U59,"") | T59: =IFERROR(M59/R59,"") | V59: =IFERROR(X59-M59,"") -> 0 | W59: =IFERROR(R59/O59,"") | X59: =IFERROR(R59*U59,"") -> 0
I60: =IFERROR(D60/H60,"") | J60: =IFERROR((E60+F60)/H60,"") | S60: =IFERROR(M60/U60,"") | T60: =IFERROR(M60/R60,"") | V60: =IFERROR(X60-M60,"") -> 0 | W60: =IFERROR(R60/O60,"") | X60: =IFERROR(R60*U60,"") -> 0
... I69: =IFERROR(D69/H69,"") | J69: =IFERROR((E69+F69)/H69,"") | S69: =IFERROR(M69/U69,"") | T69: =IFERROR(M69/R69,"") | V69: =IFERROR(X69-M69,"") -> 0 | W69: =IFERROR(R69/O69,"") | X69: =IFERROR(R69*U69,"") -> 0
...
